{"links": {"self": {"href": "data/repositories/labscript_suite/lyse/issues/45/comments/49131644.json"}, "html": {"href": "#!/labscript_suite/lyse/issues/45#comment-49131644"}}, "issue": {"links": {"self": {"href": "data/repositories/labscript_suite/lyse/issues/45.json"}}, "type": "issue", "id": 45, "repository": {"links": {"self": {"href": "data/repositories/labscript_suite/lyse.json"}, "html": {"href": "#!/labscript_suite/lyse"}, "avatar": {"href": "data/bytebucket.org/ravatar/{55eebdfe-43d1-4ae8-9049-50c55b295397}ts=249921"}}, "type": "repository", "name": "lyse", "full_name": "labscript_suite/lyse", "uuid": "{55eebdfe-43d1-4ae8-9049-50c55b295397}"}, "title": "Dataframe stopped updating after multishot routine error"}, "content": {"raw": "I don't suppose you have a log file covering the time of the error?", "markup": "markdown", "html": "<p>I don't suppose you have a log file covering the time of the error?</p>", "type": "rendered"}, "created_on": "2018-11-26T23:31:16.368860+00:00", "user": {"display_name": "Philip Starkey", "uuid": "{48af65db-e5fc-459c-a7eb-52eb1f9a5690}", "links": {"self": {"href": "https://api.bitbucket.org/2.0/users/%7B48af65db-e5fc-459c-a7eb-52eb1f9a5690%7D"}, "html": {"href": "https://bitbucket.org/%7B48af65db-e5fc-459c-a7eb-52eb1f9a5690%7D/"}, "avatar": {"href": "data/secure.gravatar.com/avatar/dc318537facc47ebe1ae98a7aabacecfd=httpsavatar-management--avatars.us-west-2.prod.public.atl-paas.netinitialsPS-0.png"}}, "nickname": "pstarkey", "type": "user", "account_id": "557058:52a111e4-40da-4441-9143-417f95f2db97"}, "updated_on": null, "type": "issue_comment", "id": 49131644}