{"priority": "minor", "kind": "bug", "repository": {"links": {"self": {"href": "data/repositories/labscript_suite/labscript_utils.json"}, "html": {"href": "#!/labscript_suite/labscript_utils"}, "avatar": {"href": "data/bytebucket.org/ravatar/{68347210-fb1e-4b58-86c0-bd2c04396e63}ts=249922"}}, "type": "repository", "name": "labscript_utils", "full_name": "labscript_suite/labscript_utils", "uuid": "{68347210-fb1e-4b58-86c0-bd2c04396e63}"}, "links": {"attachments": {"href": "data/repositories/labscript_suite/labscript_utils/issues/17/attachments_page=1.json"}, "self": {"href": "data/repositories/labscript_suite/labscript_utils/issues/17.json"}, "watch": {"href": "https://api.bitbucket.org/2.0/repositories/labscript_suite/labscript_utils/issues/17/watch"}, "comments": {"href": "data/repositories/labscript_suite/labscript_utils/issues/17/comments_page=1.json"}, "html": {"href": "#!/labscript_suite/labscript_utils/issues/17/runtimeerror-dictionary-changed-size"}, "vote": {"href": "https://api.bitbucket.org/2.0/repositories/labscript_suite/labscript_utils/issues/17/vote"}}, "reporter": {"display_name": "fretchen", "uuid": "{b6b916e1-4953-477a-9f8e-fd6c910a01a4}", "links": {"self": {"href": "https://api.bitbucket.org/2.0/users/%7Bb6b916e1-4953-477a-9f8e-fd6c910a01a4%7D"}, "html": {"href": "https://bitbucket.org/%7Bb6b916e1-4953-477a-9f8e-fd6c910a01a4%7D/"}, "avatar": {"href": "data/secure.gravatar.com/avatar/5b2ed07ddccdb457c8862cc2b3ce6fbed=httpsavatar-management--avatars.us-west-2.prod.public.atl-paas.netinitialsF-2.png"}}, "nickname": "fretchen", "type": "user", "account_id": "557058:cd123654-63a1-43af-be5e-8c5e274f4b65"}, "title": "RuntimeError: dictionary changed size during iteration", "component": null, "votes": 0, "watches": 1, "content": {"raw": "If I run labscript_utils in python3 this error is raised. \r\n\r\n\r\n```\r\n\r\nlabscript_utils/double_import_denier.py\", line 67, in __init__\r\n    for name, module in sys.modules.items():\r\nRuntimeError: dictionary changed size during iteration\r\n```\r\n\r\nIt would seem that this is a [known issue](https://stackoverflow.com/questions/11941817/how-to-avoid-runtimeerror-dictionary-changed-size-during-iteration-error)", "markup": "markdown", "html": "<p>If I run labscript_utils in python3 this error is raised. </p>\n<div class=\"codehilite\"><pre><span></span>labscript_utils/double_import_denier.py&quot;, line 67, in __init__\n    for name, module in sys.modules.items():\nRuntimeError: dictionary changed size during iteration\n</pre></div>\n\n\n<p>It would seem that this is a <a data-is-external-link=\"true\" href=\"https://stackoverflow.com/questions/11941817/how-to-avoid-runtimeerror-dictionary-changed-size-during-iteration-error\" rel=\"nofollow\">known issue</a></p>", "type": "rendered"}, "assignee": null, "state": "resolved", "version": null, "edited_on": null, "created_on": "2018-04-20T11:58:37.307532+00:00", "milestone": null, "updated_on": "2018-04-24T01:10:21.907148+00:00", "type": "issue", "id": 17}