{"links": {"self": {"href": "data/repositories/labscript_suite/labscript_utils/pullrequests/85/comments/103202138.json"}, "html": {"href": "#!/labscript_suite/labscript_utils/pull-requests/85/_/diff#comment-103202138"}}, "deleted": false, "pullrequest": {"type": "pullrequest", "id": 85, "links": {"self": {"href": "data/repositories/labscript_suite/labscript_utils/pullrequests/85.json"}, "html": {"href": "#!/labscript_suite/labscript_utils/pull-requests/85"}}, "title": "Add fix_shortcuts() function and catch DLL load error"}, "content": {"raw": "Thanks for all the advices for testing. the outputbox is working fine \\(printing a lot of funny stuff :smiley: \\) and I think there is only conda python installed. We basically updated from some labscript version at the end of april \\(25th of April/ labscript\\_utils 2.12.3 and all changes from before in all labscript programs\\). For updating we upgraded zprocess to 2.15.1 but also tried 2.12.5 \\(which was the old one\\) and some in between.\n\nThe tracelog file and the faulthandler output \\(at least what I could copy from the terminal\\) can be found here: [https://www.dropbox.com/sh/26hpobyjtljtogn/AAA4fCAUs94L86KDZZdyPMVva?dl=0](https://www.dropbox.com/sh/26hpobyjtljtogn/AAA4fCAUs94L86KDZZdyPMVva?dl=0)  \n\nIn the tracelog in line 1233 there is a very long wait which I find strange but python keeps running.", "markup": "markdown", "html": "<p>Thanks for all the advices for testing. the outputbox is working fine (printing a lot of funny stuff <img class=\"emoji\" src=\"data/pf-emoji-service--cdn.us-east-1.prod.public.atl-paas.net/standard/551c9814-1d37-4573-819d-afab3afeaf32/48x48/1f603.png\" alt=\"\ud83d\ude03\" title=\":smiley:\" data-emoji-short-name=\":smiley:\" /> ) and I think there is only conda python installed. We basically updated from some labscript version at the end of april (25th of April/ labscript_utils 2.12.3 and all changes from before in all labscript programs). For updating we upgraded zprocess to 2.15.1 but also tried 2.12.5 (which was the old one) and some in between.</p>\n<p>The tracelog file and the faulthandler output (at least what I could copy from the terminal) can be found here: <a data-is-external-link=\"true\" href=\"https://www.dropbox.com/sh/26hpobyjtljtogn/AAA4fCAUs94L86KDZZdyPMVva?dl=0\" rel=\"nofollow\">https://www.dropbox.com/sh/26hpobyjtljtogn/AAA4fCAUs94L86KDZZdyPMVva?dl=0</a>  </p>\n<p>In the tracelog in line 1233 there is a very long wait which I find strange but python keeps running.</p>", "type": "rendered"}, "created_on": "2019-05-23T17:29:32.742849+00:00", "user": {"display_name": "Lars Kohfahl", "uuid": "{14b59397-cbc0-4d8c-8a4a-fe99fb4d2d4a}", "links": {"self": {"href": "https://api.bitbucket.org/2.0/users/%7B14b59397-cbc0-4d8c-8a4a-fe99fb4d2d4a%7D"}, "html": {"href": "https://bitbucket.org/%7B14b59397-cbc0-4d8c-8a4a-fe99fb4d2d4a%7D/"}, "avatar": {"href": "data/secure.gravatar.com/avatar/630642264cd55e22515678a3a0489ac7d=httpsavatar-management--avatars.us-west-2.prod.public.atl-paas.netinitialsLK-2.png"}}, "nickname": "lkohfahl", "type": "user", "account_id": "5aafc5d11396802a57aa7f3b"}, "updated_on": "2019-05-23T17:29:32.896569+00:00", "type": "pullrequest_comment", "id": 103202138}