{"priority": "critical", "kind": "bug", "repository": {"links": {"self": {"href": "data/repositories/labscript_suite/blacs.json"}, "html": {"href": "#!/labscript_suite/blacs"}, "avatar": {"href": "data/bytebucket.org/ravatar/{50ed1eb9-8c1b-4afe-a8b8-8e0a33b39a05}ts=249915"}}, "type": "repository", "name": "BLACS", "full_name": "labscript_suite/blacs", "uuid": "{50ed1eb9-8c1b-4afe-a8b8-8e0a33b39a05}"}, "links": {"attachments": {"href": "data/repositories/labscript_suite/blacs/issues/22/attachments_page=1.json"}, "self": {"href": "data/repositories/labscript_suite/blacs/issues/22.json"}, "watch": {"href": "https://api.bitbucket.org/2.0/repositories/labscript_suite/blacs/issues/22/watch"}, "comments": {"href": "data/repositories/labscript_suite/blacs/issues/22/comments_page=1.json"}, "html": {"href": "#!/labscript_suite/blacs/issues/22/blacs-log-file-rollover-not-working"}, "vote": {"href": "https://api.bitbucket.org/2.0/repositories/labscript_suite/blacs/issues/22/vote"}}, "reporter": {"display_name": "David Meyer", "uuid": "{8df655d6-8661-4957-b4ba-669cef19bf2d}", "links": {"self": {"href": "https://api.bitbucket.org/2.0/users/%7B8df655d6-8661-4957-b4ba-669cef19bf2d%7D"}, "html": {"href": "https://bitbucket.org/%7B8df655d6-8661-4957-b4ba-669cef19bf2d%7D/"}, "avatar": {"href": "data/secure.gravatar.com/avatar/2a4efe81a17e5aeccdbc4ef2ca2cc463d=httpsavatar-management--avatars.us-west-2.prod.public.atl-paas.netinitialsDM-0.png"}}, "nickname": "dihm", "type": "user", "account_id": "557058:411f7712-e1fa-438c-b578-0359da2d9f06"}, "title": "BLACS log file rollover not working", "component": null, "votes": 0, "watches": 4, "content": {"raw": "I know this used to work when first implemented a few months back, but now my log rollover is no longer working due to file locks. The error I get is:\r\n\r\n```\r\n#!python\r\nTraceback (most recent call last):\r\n\tFile \"C:\\Anaconda2\\envs\\labscript\\lib\\logging\\handlers.py\", line 77, in emit self.doRollover()\r\n\tFile \"C:\\Anaconda2\\envs\\labscript\\lib\\logging\\handlers.py\", line 142, in emit self.doRollover()\r\n\tos.rename(self.baseFilename, dfn)\r\n\tWindowsError: [Error 32] The process cannot access the file because it is being used by another process\r\n\tLogged from file tab_base_classes.py, line 632 (or 636 or 727)\r\n```\r\nor \r\n```\r\nLogged from file __main__.py, line 584 or 603\r\n```\r\nor \r\n```\r\nLogged from file queue.py, line 828\r\n```\r\ndepending on what BLACS is doing.", "markup": "markdown", "html": "<p>I know this used to work when first implemented a few months back, but now my log rollover is no longer working due to file locks. The error I get is:</p>\n<div class=\"codehilite language-python\"><pre><span></span><span class=\"n\">Traceback</span> <span class=\"p\">(</span><span class=\"n\">most</span> <span class=\"n\">recent</span> <span class=\"n\">call</span> <span class=\"n\">last</span><span class=\"p\">):</span>\n    <span class=\"n\">File</span> <span class=\"s2\">&quot;C:\\Anaconda2\\envs\\labscript\\lib\\logging\\handlers.py&quot;</span><span class=\"p\">,</span> <span class=\"n\">line</span> <span class=\"mi\">77</span><span class=\"p\">,</span> <span class=\"ow\">in</span> <span class=\"n\">emit</span> <span class=\"bp\">self</span><span class=\"o\">.</span><span class=\"n\">doRollover</span><span class=\"p\">()</span>\n    <span class=\"n\">File</span> <span class=\"s2\">&quot;C:\\Anaconda2\\envs\\labscript\\lib\\logging\\handlers.py&quot;</span><span class=\"p\">,</span> <span class=\"n\">line</span> <span class=\"mi\">142</span><span class=\"p\">,</span> <span class=\"ow\">in</span> <span class=\"n\">emit</span> <span class=\"bp\">self</span><span class=\"o\">.</span><span class=\"n\">doRollover</span><span class=\"p\">()</span>\n    <span class=\"n\">os</span><span class=\"o\">.</span><span class=\"n\">rename</span><span class=\"p\">(</span><span class=\"bp\">self</span><span class=\"o\">.</span><span class=\"n\">baseFilename</span><span class=\"p\">,</span> <span class=\"n\">dfn</span><span class=\"p\">)</span>\n    <span class=\"ne\">WindowsError</span><span class=\"p\">:</span> <span class=\"p\">[</span><span class=\"n\">Error</span> <span class=\"mi\">32</span><span class=\"p\">]</span> <span class=\"n\">The</span> <span class=\"n\">process</span> <span class=\"n\">cannot</span> <span class=\"n\">access</span> <span class=\"n\">the</span> <span class=\"nb\">file</span> <span class=\"n\">because</span> <span class=\"n\">it</span> <span class=\"ow\">is</span> <span class=\"n\">being</span> <span class=\"n\">used</span> <span class=\"n\">by</span> <span class=\"n\">another</span> <span class=\"n\">process</span>\n    <span class=\"n\">Logged</span> <span class=\"kn\">from</span> <span class=\"nn\">file</span> <span class=\"nn\">tab_base_classes.py</span><span class=\"p\">,</span> <span class=\"n\">line</span> <span class=\"mi\">632</span> <span class=\"p\">(</span><span class=\"ow\">or</span> <span class=\"mi\">636</span> <span class=\"ow\">or</span> <span class=\"mi\">727</span><span class=\"p\">)</span>\n</pre></div>\n\n\n<p>or </p>\n<div class=\"codehilite\"><pre><span></span>Logged from file __main__.py, line 584 or 603\n</pre></div>\n\n\n<p>or </p>\n<div class=\"codehilite\"><pre><span></span>Logged from file queue.py, line 828\n</pre></div>\n\n\n<p>depending on what BLACS is doing.</p>", "type": "rendered"}, "assignee": {"display_name": "Chris Billington", "uuid": "{e363c5a9-5075-4656-afb5-88bd6a6dceeb}", "links": {"self": {"href": "https://api.bitbucket.org/2.0/users/%7Be363c5a9-5075-4656-afb5-88bd6a6dceeb%7D"}, "html": {"href": "https://bitbucket.org/%7Be363c5a9-5075-4656-afb5-88bd6a6dceeb%7D/"}, "avatar": {"href": "data/secure.gravatar.com/avatar/9238baf7300c41c0e7294db922899e6ad=httpsavatar-management--avatars.us-west-2.prod.public.atl-paas.netinitialsCB-1.png"}}, "nickname": "cbillington", "type": "user", "account_id": "557058:cbf1bc43-1dc2-477b-9e25-1a8f40fd7ee3"}, "state": "resolved", "version": null, "edited_on": null, "created_on": "2017-06-23T20:54:30.420054+00:00", "milestone": null, "updated_on": "2018-10-17T15:25:55.272922+00:00", "type": "issue", "id": 22}