{"priority": "major", "kind": "bug", "repository": {"links": {"self": {"href": "data/repositories/labscript_suite/lyse.json"}, "html": {"href": "#!/labscript_suite/lyse"}, "avatar": {"href": "data/bytebucket.org/ravatar/{55eebdfe-43d1-4ae8-9049-50c55b295397}ts=249921"}}, "type": "repository", "name": "lyse", "full_name": "labscript_suite/lyse", "uuid": "{55eebdfe-43d1-4ae8-9049-50c55b295397}"}, "links": {"attachments": {"href": "data/repositories/labscript_suite/lyse/issues/28/attachments_page=1.json"}, "self": {"href": "data/repositories/labscript_suite/lyse/issues/28.json"}, "watch": {"href": "https://api.bitbucket.org/2.0/repositories/labscript_suite/lyse/issues/28/watch"}, "comments": {"href": "data/repositories/labscript_suite/lyse/issues/28/comments_page=1.json"}, "html": {"href": "#!/labscript_suite/lyse/issues/28/lyse-doesnt-handle-unicode-well"}, "vote": {"href": "https://api.bitbucket.org/2.0/repositories/labscript_suite/lyse/issues/28/vote"}}, "reporter": {"display_name": "Jan Werkmann", "uuid": "{44c4905c-2b90-4045-a5f1-652b8e228626}", "links": {"self": {"href": "https://api.bitbucket.org/2.0/users/%7B44c4905c-2b90-4045-a5f1-652b8e228626%7D"}, "html": {"href": "https://bitbucket.org/%7B44c4905c-2b90-4045-a5f1-652b8e228626%7D/"}, "avatar": {"href": "https://avatar-management--avatars.us-west-2.prod.public.atl-paas.net/557058:a70cc9cf-684e-4849-a61a-9ade4d7218b5/07e5095a-4741-4dc0-a462-9c7d455f961d/128"}}, "nickname": "PhyNerd", "type": "user", "account_id": "557058:a70cc9cf-684e-4849-a61a-9ade4d7218b5"}, "title": "Lyse doesn't handle unicode well", "component": null, "votes": 0, "watches": 2, "content": {"raw": "If you import scripts into lyse that include non ascii characters in their name (such as german Umlauts) the script will not run.\r\n\r\nIf you modify analysis_subprocess.py in line 288 in the following way scripts will run:\r\n\r\n```\r\n#!python\r\n\r\nexecfile(self.filepath.encode('utf-8'), sandbox, sandbox)\r\n```\r\n\r\nHowever if that script then crashed lyse will crash along with it and give you this traceback:\r\n\r\n\r\n```\r\n#!\r\n\r\nTraceback (most recent call last):\r\n  File \"/Users/janwerkmann/anaconda/lib/python2.7/threading.py\", line 754, in run\r\n    self.__target(*self.__args, **self.__kwargs)\r\n  File \"analysis_subprocess.py\", line 257, in mainloop\r\n    success = self.do_analysis(path)\r\n  File \"/Users/janwerkmann/anaconda/lib/python2.7/site-packages/qtutils/invoke_in_main.py\", line 114, in f\r\n    return inmain(fn, *args, **kwargs)\r\n  File \"/Users/janwerkmann/anaconda/lib/python2.7/site-packages/qtutils/invoke_in_main.py\", line 74, in inmain\r\n    return get_inmain_result(in_main_later(fn,False,*args,**kwargs))\r\n  File \"/Users/janwerkmann/anaconda/lib/python2.7/site-packages/qtutils/invoke_in_main.py\", line 94, in get_inmain_result\r\n    exec('raise type, value, traceback')\r\n  File \"/Users/janwerkmann/anaconda/lib/python2.7/site-packages/qtutils/invoke_in_main.py\", line 53, in event\r\n    result = event.fn(*event.args, **event.kwargs)\r\n  File \"analysis_subprocess.py\", line 297, in do_analysis\r\n    print('%s' % message)\r\n  File \"/Users/janwerkmann/anaconda/lib/python2.7/site-packages/zprocess/__init__.py\", line 455, in write\r\n    self.local.sock.send_multipart([self.streamname.encode('utf8'), s.encode('utf8')])\r\nUnicodeDecodeError: 'ascii' codec can't decode byte 0xcc in position 91: ordinal not in range(128)\r\n```", "markup": "markdown", "html": "<p>If you import scripts into lyse that include non ascii characters in their name (such as german Umlauts) the script will not run.</p>\n<p>If you modify analysis_subprocess.py in line 288 in the following way scripts will run:</p>\n<div class=\"codehilite language-python\"><pre><span></span><span class=\"nb\">execfile</span><span class=\"p\">(</span><span class=\"bp\">self</span><span class=\"o\">.</span><span class=\"n\">filepath</span><span class=\"o\">.</span><span class=\"n\">encode</span><span class=\"p\">(</span><span class=\"s1\">&#39;utf-8&#39;</span><span class=\"p\">),</span> <span class=\"n\">sandbox</span><span class=\"p\">,</span> <span class=\"n\">sandbox</span><span class=\"p\">)</span>\n</pre></div>\n\n\n<p>However if that script then crashed lyse will crash along with it and give you this traceback:</p>\n<div class=\"codehilite\"><pre><span></span>Traceback (most recent call last):\n  File &quot;/Users/janwerkmann/anaconda/lib/python2.7/threading.py&quot;, line 754, in run\n    self.__target(*self.__args, **self.__kwargs)\n  File &quot;analysis_subprocess.py&quot;, line 257, in mainloop\n    success = self.do_analysis(path)\n  File &quot;/Users/janwerkmann/anaconda/lib/python2.7/site-packages/qtutils/invoke_in_main.py&quot;, line 114, in f\n    return inmain(fn, *args, **kwargs)\n  File &quot;/Users/janwerkmann/anaconda/lib/python2.7/site-packages/qtutils/invoke_in_main.py&quot;, line 74, in inmain\n    return get_inmain_result(in_main_later(fn,False,*args,**kwargs))\n  File &quot;/Users/janwerkmann/anaconda/lib/python2.7/site-packages/qtutils/invoke_in_main.py&quot;, line 94, in get_inmain_result\n    exec(&#39;raise type, value, traceback&#39;)\n  File &quot;/Users/janwerkmann/anaconda/lib/python2.7/site-packages/qtutils/invoke_in_main.py&quot;, line 53, in event\n    result = event.fn(*event.args, **event.kwargs)\n  File &quot;analysis_subprocess.py&quot;, line 297, in do_analysis\n    print(&#39;%s&#39; % message)\n  File &quot;/Users/janwerkmann/anaconda/lib/python2.7/site-packages/zprocess/__init__.py&quot;, line 455, in write\n    self.local.sock.send_multipart([self.streamname.encode(&#39;utf8&#39;), s.encode(&#39;utf8&#39;)])\nUnicodeDecodeError: &#39;ascii&#39; codec can&#39;t decode byte 0xcc in position 91: ordinal not in range(128)\n</pre></div>", "type": "rendered"}, "assignee": {"display_name": "Chris Billington", "uuid": "{e363c5a9-5075-4656-afb5-88bd6a6dceeb}", "links": {"self": {"href": "https://api.bitbucket.org/2.0/users/%7Be363c5a9-5075-4656-afb5-88bd6a6dceeb%7D"}, "html": {"href": "https://bitbucket.org/%7Be363c5a9-5075-4656-afb5-88bd6a6dceeb%7D/"}, "avatar": {"href": "data/secure.gravatar.com/avatar/9238baf7300c41c0e7294db922899e6ad=httpsavatar-management--avatars.us-west-2.prod.public.atl-paas.netinitialsCB-1.png"}}, "nickname": "cbillington", "type": "user", "account_id": "557058:cbf1bc43-1dc2-477b-9e25-1a8f40fd7ee3"}, "state": "resolved", "version": null, "edited_on": null, "created_on": "2017-07-07T10:11:51.855512+00:00", "milestone": null, "updated_on": "2018-02-26T00:20:21.997827+00:00", "type": "issue", "id": 28}