{"links": {"self": {"href": "data/repositories/labscript_suite/labscript_utils/issues/17/comments/44845251.json"}, "html": {"href": "#!/labscript_suite/labscript_utils/issues/17#comment-44845251"}}, "issue": {"links": {"self": {"href": "data/repositories/labscript_suite/labscript_utils/issues/17.json"}}, "type": "issue", "id": 17, "repository": {"links": {"self": {"href": "data/repositories/labscript_suite/labscript_utils.json"}, "html": {"href": "#!/labscript_suite/labscript_utils"}, "avatar": {"href": "data/bytebucket.org/ravatar/{68347210-fb1e-4b58-86c0-bd2c04396e63}ts=249922"}}, "type": "repository", "name": "labscript_utils", "full_name": "labscript_suite/labscript_utils", "uuid": "{68347210-fb1e-4b58-86c0-bd2c04396e63}"}, "title": "RuntimeError: dictionary changed size during iteration"}, "content": {"raw": "Hi Chris,\n\nthe error is raise within the following context:\n\n\n```\n#!python\n\nfrom app import app\nfrom app.forms import LoginForm, FileForm\nfrom flask import render_template, flash, redirect\nimport labscript_utils\n\nfrom lyse import *\n```\n\nOne should also know that I did not go through the full installer as I want to have some flexibility on where I install lyse etc later-on. In the meantime, I found that running this many times the error disappears. So the bug still remains, but I have a hard time understanding it.", "markup": "markdown", "html": "<p>Hi Chris,</p>\n<p>the error is raise within the following context:</p>\n<div class=\"codehilite language-python\"><pre><span></span><span class=\"kn\">from</span> <span class=\"nn\">app</span> <span class=\"kn\">import</span> <span class=\"n\">app</span>\n<span class=\"kn\">from</span> <span class=\"nn\">app.forms</span> <span class=\"kn\">import</span> <span class=\"n\">LoginForm</span><span class=\"p\">,</span> <span class=\"n\">FileForm</span>\n<span class=\"kn\">from</span> <span class=\"nn\">flask</span> <span class=\"kn\">import</span> <span class=\"n\">render_template</span><span class=\"p\">,</span> <span class=\"n\">flash</span><span class=\"p\">,</span> <span class=\"n\">redirect</span>\n<span class=\"kn\">import</span> <span class=\"nn\">labscript_utils</span>\n\n<span class=\"kn\">from</span> <span class=\"nn\">lyse</span> <span class=\"kn\">import</span> <span class=\"o\">*</span>\n</pre></div>\n\n\n<p>One should also know that I did not go through the full installer as I want to have some flexibility on where I install lyse etc later-on. In the meantime, I found that running this many times the error disappears. So the bug still remains, but I have a hard time understanding it.</p>", "type": "rendered"}, "created_on": "2018-04-20T14:01:35.119068+00:00", "user": {"display_name": "fretchen", "uuid": "{b6b916e1-4953-477a-9f8e-fd6c910a01a4}", "links": {"self": {"href": "https://api.bitbucket.org/2.0/users/%7Bb6b916e1-4953-477a-9f8e-fd6c910a01a4%7D"}, "html": {"href": "https://bitbucket.org/%7Bb6b916e1-4953-477a-9f8e-fd6c910a01a4%7D/"}, "avatar": {"href": "data/secure.gravatar.com/avatar/5b2ed07ddccdb457c8862cc2b3ce6fbed=httpsavatar-management--avatars.us-west-2.prod.public.atl-paas.netinitialsF-2.png"}}, "nickname": "fretchen", "type": "user", "account_id": "557058:cd123654-63a1-43af-be5e-8c5e274f4b65"}, "updated_on": null, "type": "issue_comment", "id": 44845251}