{"rendered": {"message": {"raw": "Fix two issues with delayed closing of lyse\n\n* There was a bug where if no configuration changed, Lyse.on_close_event\n  would not terminate the subprocesses, and then it would wait the full\n  two seconds before quitting (and potentially leave any non-zprocess subprocesses\n  running). Refactored on_close_event(), factoring out the 'are you sure' dialog\n  and the termination of all subprocesses into separate functions while fixing\n  the logic here.\n* When lyse was to actually quit, it called qapplication.quit() instead of .close()\n  on the main window. This means if running with `python -i`, lyse doesn't actually\n  close, as the event loop just fires back up again. Now it actally calls close(),\n  and this triggers the same method that caught the first close event, which knows\n  it's the second time it's been called because a flag has been set so actually closes.\n  This also has the side effect that the user clicking close twice will close\n  lyse regardless of the timeout (which seems fine).", "markup": "markdown", "html": "<p>Fix two issues with delayed closing of lyse</p>\n<ul>\n<li>There was a bug where if no configuration changed, Lyse.on_close_event<br />\n  would not terminate the subprocesses, and then it would wait the full<br />\n  two seconds before quitting (and potentially leave any non-zprocess subprocesses<br />\n  running). Refactored on_close_event(), factoring out the 'are you sure' dialog<br />\n  and the termination of all subprocesses into separate functions while fixing<br />\n  the logic here.</li>\n<li>When lyse was to actually quit, it called qapplication.quit() instead of .close()<br />\n  on the main window. This means if running with <code>python -i</code>, lyse doesn't actually<br />\n  close, as the event loop just fires back up again. Now it actally calls close(),<br />\n  and this triggers the same method that caught the first close event, which knows<br />\n  it's the second time it's been called because a flag has been set so actually closes.<br />\n  This also has the side effect that the user clicking close twice will close<br />\n  lyse regardless of the timeout (which seems fine).</li>\n</ul>", "type": "rendered"}}, "hash": "efe00aa15132b0ab8a7127d3c0ec4c136da7bcd1", "repository": {"links": {"self": {"href": "data/repositories/labscript_suite/lyse.json"}, "html": {"href": "#!/labscript_suite/lyse"}, "avatar": {"href": "data/bytebucket.org/ravatar/{55eebdfe-43d1-4ae8-9049-50c55b295397}ts=249921"}}, "type": "repository", "name": "lyse", "full_name": "labscript_suite/lyse", "uuid": "{55eebdfe-43d1-4ae8-9049-50c55b295397}"}, "links": {"self": {"href": "data/repositories/labscript_suite/lyse/commit/efe00aa15132b0ab8a7127d3c0ec4c136da7bcd1.json"}, "comments": {"href": "data/repositories/labscript_suite/lyse/commit/efe00aa15132b0ab8a7127d3c0ec4c136da7bcd1/comments_page=1.json"}, "patch": {"href": "https://api.bitbucket.org/2.0/repositories/labscript_suite/lyse/patch/efe00aa15132b0ab8a7127d3c0ec4c136da7bcd1"}, "html": {"href": "#!/labscript_suite/lyse/commits/efe00aa15132b0ab8a7127d3c0ec4c136da7bcd1"}, "diff": {"href": "https://api.bitbucket.org/2.0/repositories/labscript_suite/lyse/diff/efe00aa15132b0ab8a7127d3c0ec4c136da7bcd1"}, "approve": {"href": "https://api.bitbucket.org/2.0/repositories/labscript_suite/lyse/commit/efe00aa15132b0ab8a7127d3c0ec4c136da7bcd1/approve"}, "statuses": {"href": "data/repositories/labscript_suite/lyse/commit/efe00aa15132b0ab8a7127d3c0ec4c136da7bcd1/statuses_page=1.json"}}, "author": {"raw": "chrisjbillington", "type": "author", "user": {"display_name": "Chris Billington", "uuid": "{e363c5a9-5075-4656-afb5-88bd6a6dceeb}", "links": {"self": {"href": "https://api.bitbucket.org/2.0/users/%7Be363c5a9-5075-4656-afb5-88bd6a6dceeb%7D"}, "html": {"href": "https://bitbucket.org/%7Be363c5a9-5075-4656-afb5-88bd6a6dceeb%7D/"}, "avatar": {"href": "data/secure.gravatar.com/avatar/9238baf7300c41c0e7294db922899e6ad=httpsavatar-management--avatars.us-west-2.prod.public.atl-paas.netinitialsCB-1.png"}}, "nickname": "cbillington", "type": "user", "account_id": "557058:cbf1bc43-1dc2-477b-9e25-1a8f40fd7ee3"}}, "summary": {"raw": "Fix two issues with delayed closing of lyse\n\n* There was a bug where if no configuration changed, Lyse.on_close_event\n  would not terminate the subprocesses, and then it would wait the full\n  two seconds before quitting (and potentially leave any non-zprocess subprocesses\n  running). Refactored on_close_event(), factoring out the 'are you sure' dialog\n  and the termination of all subprocesses into separate functions while fixing\n  the logic here.\n* When lyse was to actually quit, it called qapplication.quit() instead of .close()\n  on the main window. This means if running with `python -i`, lyse doesn't actually\n  close, as the event loop just fires back up again. Now it actally calls close(),\n  and this triggers the same method that caught the first close event, which knows\n  it's the second time it's been called because a flag has been set so actually closes.\n  This also has the side effect that the user clicking close twice will close\n  lyse regardless of the timeout (which seems fine).", "markup": "markdown", "html": "<p>Fix two issues with delayed closing of lyse</p>\n<ul>\n<li>There was a bug where if no configuration changed, Lyse.on_close_event<br />\n  would not terminate the subprocesses, and then it would wait the full<br />\n  two seconds before quitting (and potentially leave any non-zprocess subprocesses<br />\n  running). Refactored on_close_event(), factoring out the 'are you sure' dialog<br />\n  and the termination of all subprocesses into separate functions while fixing<br />\n  the logic here.</li>\n<li>When lyse was to actually quit, it called qapplication.quit() instead of .close()<br />\n  on the main window. This means if running with <code>python -i</code>, lyse doesn't actually<br />\n  close, as the event loop just fires back up again. Now it actally calls close(),<br />\n  and this triggers the same method that caught the first close event, which knows<br />\n  it's the second time it's been called because a flag has been set so actually closes.<br />\n  This also has the side effect that the user clicking close twice will close<br />\n  lyse regardless of the timeout (which seems fine).</li>\n</ul>", "type": "rendered"}, "participants": [], "parents": [{"hash": "e8dda2f57f682689ac91576c5b2087c1f8f1dca8", "type": "commit", "links": {"self": {"href": "data/repositories/labscript_suite/lyse/commit/e8dda2f57f682689ac91576c5b2087c1f8f1dca8.json"}, "html": {"href": "#!/labscript_suite/lyse/commits/e8dda2f57f682689ac91576c5b2087c1f8f1dca8"}}}], "date": "2019-05-10T01:12:34+00:00", "message": "Fix two issues with delayed closing of lyse\n\n* There was a bug where if no configuration changed, Lyse.on_close_event\n  would not terminate the subprocesses, and then it would wait the full\n  two seconds before quitting (and potentially leave any non-zprocess subprocesses\n  running). Refactored on_close_event(), factoring out the 'are you sure' dialog\n  and the termination of all subprocesses into separate functions while fixing\n  the logic here.\n* When lyse was to actually quit, it called qapplication.quit() instead of .close()\n  on the main window. This means if running with `python -i`, lyse doesn't actually\n  close, as the event loop just fires back up again. Now it actally calls close(),\n  and this triggers the same method that caught the first close event, which knows\n  it's the second time it's been called because a flag has been set so actually closes.\n  This also has the side effect that the user clicking close twice will close\n  lyse regardless of the timeout (which seems fine).", "type": "commit", "git_hash": "bd48f9e87df78115d3f9f289ed59602a298a8979", "tags": null, "branches": "bugfix"}