{"links": {"self": {"href": "data/repositories/labscript_suite/lyse/issues/25/comments/37723620.json"}, "html": {"href": "#!/labscript_suite/lyse/issues/25#comment-37723620"}}, "issue": {"links": {"self": {"href": "data/repositories/labscript_suite/lyse/issues/25.json"}}, "type": "issue", "id": 25, "repository": {"links": {"self": {"href": "data/repositories/labscript_suite/lyse.json"}, "html": {"href": "#!/labscript_suite/lyse"}, "avatar": {"href": "data/bytebucket.org/ravatar/{55eebdfe-43d1-4ae8-9049-50c55b295397}ts=249921"}}, "type": "repository", "name": "lyse", "full_name": "labscript_suite/lyse", "uuid": "{55eebdfe-43d1-4ae8-9049-50c55b295397}"}, "title": "Plots don't update after error"}, "content": {"raw": "Thanks for the report. This is surprising! I'll see if I can reproduce the problem.", "markup": "markdown", "html": "<p>Thanks for the report. This is surprising! I'll see if I can reproduce the problem.</p>", "type": "rendered"}, "created_on": "2017-06-20T17:23:06.399276+00:00", "user": {"display_name": "Chris Billington", "uuid": "{e363c5a9-5075-4656-afb5-88bd6a6dceeb}", "links": {"self": {"href": "https://api.bitbucket.org/2.0/users/%7Be363c5a9-5075-4656-afb5-88bd6a6dceeb%7D"}, "html": {"href": "https://bitbucket.org/%7Be363c5a9-5075-4656-afb5-88bd6a6dceeb%7D/"}, "avatar": {"href": "data/secure.gravatar.com/avatar/9238baf7300c41c0e7294db922899e6ad=httpsavatar-management--avatars.us-west-2.prod.public.atl-paas.netinitialsCB-1.png"}}, "nickname": "cbillington", "type": "user", "account_id": "557058:cbf1bc43-1dc2-477b-9e25-1a8f40fd7ee3"}, "updated_on": null, "type": "issue_comment", "id": 37723620}