{"links": {"self": {"href": "data/repositories/labscript_suite/lyse/pullrequests/31/comments/43047181.json"}, "html": {"href": "#!/labscript_suite/lyse/pull-requests/31/_/diff#comment-43047181"}}, "parent": {"id": 43044286, "links": {"self": {"href": "data/repositories/labscript_suite/lyse/pullrequests/31/comments/43044286.json"}, "html": {"href": "#!/labscript_suite/lyse/pull-requests/31/_/diff#comment-43044286"}}}, "deleted": false, "pullrequest": {"type": "pullrequest", "id": 31, "links": {"self": {"href": "data/repositories/labscript_suite/lyse/pullrequests/31.json"}, "html": {"href": "#!/labscript_suite/lyse/pull-requests/31"}}, "title": "Fix a bug in updating the dataframe"}, "content": {"raw": "Thanks for testing! The performance improvement is icing on the cake (36 times faster for your test code, wow!). \n\nI'm not able to reproduce in self-contained code, so I'm not sure to exactly what situation the bug applies. But if you revert lyse to before the fix, and try a save_value('x', [1, 2, 3]) from an analysis routine, that's where I get the exception.", "markup": "markdown", "html": "<p>Thanks for testing! The performance improvement is icing on the cake (36 times faster for your test code, wow!). </p>\n<p>I'm not able to reproduce in self-contained code, so I'm not sure to exactly what situation the bug applies. But if you revert lyse to before the fix, and try a save_value('x', [1, 2, 3]) from an analysis routine, that's where I get the exception.</p>", "type": "rendered"}, "created_on": "2017-08-17T19:01:29.710264+00:00", "user": {"display_name": "Chris Billington", "uuid": "{e363c5a9-5075-4656-afb5-88bd6a6dceeb}", "links": {"self": {"href": "https://api.bitbucket.org/2.0/users/%7Be363c5a9-5075-4656-afb5-88bd6a6dceeb%7D"}, "html": {"href": "https://bitbucket.org/%7Be363c5a9-5075-4656-afb5-88bd6a6dceeb%7D/"}, "avatar": {"href": "data/secure.gravatar.com/avatar/9238baf7300c41c0e7294db922899e6ad=httpsavatar-management--avatars.us-west-2.prod.public.atl-paas.netinitialsCB-1.png"}}, "nickname": "cbillington", "type": "user", "account_id": "557058:cbf1bc43-1dc2-477b-9e25-1a8f40fd7ee3"}, "updated_on": "2017-08-17T19:01:29.712510+00:00", "type": "pullrequest_comment", "id": 43047181}